Traceback (most recent call last):
  File "/home/runner/.cache/pypoetry/virtualenvs/quantflow-lUXkzsy2-py3.12/lib/python3.12/site-packages/jupyter_core/utils/__init__.py", line 154, in wrapped
    asyncio.get_running_loop()
RuntimeError: no running event loop

During handling of the above exception, another exception occurred:

Traceback (most recent call last):
  File "/home/runner/.cache/pypoetry/virtualenvs/quantflow-lUXkzsy2-py3.12/lib/python3.12/site-packages/jupyter_cache/executors/utils.py", line 58, in single_nb_execution
    executenb(
  File "/home/runner/.cache/pypoetry/virtualenvs/quantflow-lUXkzsy2-py3.12/lib/python3.12/site-packages/nbclient/client.py", line 1319, in execute
    return NotebookClient(nb=nb, resources=resources, km=km, **kwargs).execute()
           ^^^^^^^^^^^^^^^^^^^^^^^^^^^^^^^^^^^^^^^^^^^^^^^^^^^^^^^^^^^^^^^^^^^^^
  File "/home/runner/.cache/pypoetry/virtualenvs/quantflow-lUXkzsy2-py3.12/lib/python3.12/site-packages/jupyter_core/utils/__init__.py", line 158, in wrapped
    return loop.run_until_complete(inner)
           ^^^^^^^^^^^^^^^^^^^^^^^^^^^^^^
  File "/opt/hostedtoolcache/Python/3.12.11/x64/lib/python3.12/asyncio/base_events.py", line 691, in run_until_complete
    return future.result()
           ^^^^^^^^^^^^^^^
  File "/home/runner/.cache/pypoetry/virtualenvs/quantflow-lUXkzsy2-py3.12/lib/python3.12/site-packages/nbclient/client.py", line 709, in async_execute
    await self.async_execute_cell(
  File "/home/runner/.cache/pypoetry/virtualenvs/quantflow-lUXkzsy2-py3.12/lib/python3.12/site-packages/nbclient/client.py", line 1062, in async_execute_cell
    await self._check_raise_for_error(cell, cell_index, exec_reply)
  File "/home/runner/.cache/pypoetry/virtualenvs/quantflow-lUXkzsy2-py3.12/lib/python3.12/site-packages/nbclient/client.py", line 918, in _check_raise_for_error
    raise CellExecutionError.from_cell_and_msg(cell, exec_reply_content)
nbclient.exceptions.CellExecutionError: An error occurred while executing the following cell:
------------------
[p for p in pr.variance_process.parameters]
------------------


[31m---------------------------------------------------------------------------[39m
[31mAttributeError[39m                            Traceback (most recent call last)
[36mCell[39m[36m [39m[32mIn[2][39m[32m, line 1[39m
[32m----> [39m[32m1[39m [p [38;5;28;01mfor[39;00m p [38;5;129;01min[39;00m [43mpr[49m[43m.[49m[43mvariance_process[49m[43m.[49m[43mparameters[49m]

[36mFile [39m[32m~/.cache/pypoetry/virtualenvs/quantflow-lUXkzsy2-py3.12/lib/python3.12/site-packages/pydantic/main.py:991[39m, in [36mBaseModel.__getattr__[39m[34m(self, item)[39m
[32m    988[39m     [38;5;28;01mreturn[39;00m [38;5;28msuper[39m().[34m__getattribute__[39m(item)  [38;5;66;03m# Raises AttributeError if appropriate[39;00m
[32m    989[39m [38;5;28;01melse[39;00m:
[32m    990[39m     [38;5;66;03m# this is the current error[39;00m
[32m--> [39m[32m991[39m     [38;5;28;01mraise[39;00m [38;5;167;01mAttributeError[39;00m([33mf[39m[33m'[39m[38;5;132;01m{[39;00m[38;5;28mtype[39m([38;5;28mself[39m).[34m__name__[39m[38;5;132;01m!r}[39;00m[33m object has no attribute [39m[38;5;132;01m{[39;00mitem[38;5;132;01m!r}[39;00m[33m'[39m)

[31mAttributeError[39m: 'CIR' object has no attribute 'parameters'

