Traceback (most recent call last):
  File "/home/runner/.cache/pypoetry/virtualenvs/quantflow-lUXkzsy2-py3.12/lib/python3.12/site-packages/jupyter_core/utils/__init__.py", line 154, in wrapped
    asyncio.get_running_loop()
RuntimeError: no running event loop

During handling of the above exception, another exception occurred:

Traceback (most recent call last):
  File "/home/runner/.cache/pypoetry/virtualenvs/quantflow-lUXkzsy2-py3.12/lib/python3.12/site-packages/jupyter_cache/executors/utils.py", line 58, in single_nb_execution
    executenb(
  File "/home/runner/.cache/pypoetry/virtualenvs/quantflow-lUXkzsy2-py3.12/lib/python3.12/site-packages/nbclient/client.py", line 1319, in execute
    return NotebookClient(nb=nb, resources=resources, km=km, **kwargs).execute()
           ^^^^^^^^^^^^^^^^^^^^^^^^^^^^^^^^^^^^^^^^^^^^^^^^^^^^^^^^^^^^^^^^^^^^^
  File "/home/runner/.cache/pypoetry/virtualenvs/quantflow-lUXkzsy2-py3.12/lib/python3.12/site-packages/jupyter_core/utils/__init__.py", line 158, in wrapped
    return loop.run_until_complete(inner)
           ^^^^^^^^^^^^^^^^^^^^^^^^^^^^^^
  File "/opt/hostedtoolcache/Python/3.12.11/x64/lib/python3.12/asyncio/base_events.py", line 691, in run_until_complete
    return future.result()
           ^^^^^^^^^^^^^^^
  File "/home/runner/.cache/pypoetry/virtualenvs/quantflow-lUXkzsy2-py3.12/lib/python3.12/site-packages/nbclient/client.py", line 709, in async_execute
    await self.async_execute_cell(
  File "/home/runner/.cache/pypoetry/virtualenvs/quantflow-lUXkzsy2-py3.12/lib/python3.12/site-packages/nbclient/client.py", line 1062, in async_execute_cell
    await self._check_raise_for_error(cell, cell_index, exec_reply)
  File "/home/runner/.cache/pypoetry/virtualenvs/quantflow-lUXkzsy2-py3.12/lib/python3.12/site-packages/nbclient/client.py", line 918, in _check_raise_for_error
    raise CellExecutionError.from_cell_and_msg(cell, exec_reply_content)
nbclient.exceptions.CellExecutionError: An error occurred while executing the following cell:
------------------
import pandas as pd
from quantflow.utils import plot
from quantflow.utils.paths import Paths

samples = 1000
time_steps = 100

draws = Paths.normal_draws(samples, time_horizon=1, time_steps=time_steps)
mean = dict(mean=pr.marginal(draws.time).mean())
mean.update({pr.sample_algo.name: pr.sample_from_draws(draws).mean() for pr in prs})
df = pd.DataFrame(mean, index=draws.time)

plot.plot_lines(df)
------------------


[31m---------------------------------------------------------------------------[39m
[31mModuleNotFoundError[39m                       Traceback (most recent call last)
[36mCell[39m[36m [39m[32mIn[15][39m[32m, line 3[39m
[32m      1[39m [38;5;28;01mimport[39;00m[38;5;250m [39m[34;01mpandas[39;00m[38;5;250m [39m[38;5;28;01mas[39;00m[38;5;250m [39m[34;01mpd[39;00m
[32m      2[39m [38;5;28;01mfrom[39;00m[38;5;250m [39m[34;01mquantflow[39;00m[34;01m.[39;00m[34;01mutils[39;00m[38;5;250m [39m[38;5;28;01mimport[39;00m plot
[32m----> [39m[32m3[39m [38;5;28;01mfrom[39;00m[38;5;250m [39m[34;01mquantflow[39;00m[34;01m.[39;00m[34;01mutils[39;00m[34;01m.[39;00m[34;01mpaths[39;00m[38;5;250m [39m[38;5;28;01mimport[39;00m Paths
[32m      5[39m samples = [32m1000[39m
[32m      6[39m time_steps = [32m100[39m

[31mModuleNotFoundError[39m: No module named 'quantflow.utils.paths'

